Watching for file changes with StatReloader
Performing system checks...

System check identified no issues (0 silenced).
September 24, 2025 - 10:24:20
Django version 5.2.5, using settings 'settings'
Starting development server at http://127.0.0.1:8000/
Quit the server with CONTROL-C.

WARNING: This is a development server. Do not use it in a production setting. Use a production WSGI or ASGI server instead.
For more information on production servers see: https://docs.djangoproject.com/en/5.2/howto/deployment/
[24/Sep/2025 10:24:22] "GET / HTTP/1.1" 200 71632
[24/Sep/2025 10:24:22] "GET /static/core/css/site.css HTTP/1.1" 304 0
[24/Sep/2025 10:24:23] "GET /static/core/js/requests-panels.js HTTP/1.1" 304 0
[24/Sep/2025 10:24:23] "GET /static/core/js/performers-panels.js HTTP/1.1" 304 0
[24/Sep/2025 10:24:23] "GET /policy/policy/partial/ HTTP/1.1" 200 18425
[24/Sep/2025 10:24:23] "GET /projects/partial/ HTTP/1.1" 200 22372
[24/Sep/2025 10:24:23] "GET /onedrive/connections/partial/ HTTP/1.1" 200 10563
[24/Sep/2025 10:24:23] "GET /projects/performers/partial/ HTTP/1.1" 200 10153
[24/Sep/2025 10:24:23] "GET /debugger/partial/panel/ HTTP/1.1" 200 28639
[24/Sep/2025 10:24:23] "GET /requests/partial/?product=DD&section=1 HTTP/1.1" 200 8799
[24/Sep/2025 10:24:23] "GET /debugger/project-meta/13/ HTTP/1.1" 200 227
[24/Sep/2025 10:24:36] "GET /blocks/?tab=debugger&product=DD&section=4 HTTP/1.1" 200 128390
[24/Sep/2025 10:24:36] "GET /blocks/?tab=templates&product=DD&section=1 HTTP/1.1" 200 71946
RUNPROBE {"stage": "pre-view", "method": "POST", "path": "/blocks/blocks/12/run/", "qs": "", "content_type": "application/x-www-form-urlencoded", "hx": {"HX-Request": null, "HX-Trigger": null, "HX-Target": null, "HX-Boosted": null}, "raw_body_prefix": "csrfmiddlewaretoken=z44GIk9RrbjXsIGHPWYKp7zyHKhFlSA9QgZI47AP8p9df3qQkRgdij6iQtJ0UdkN&next=%2F%23debugger&product_id=&section_id=&project_code=&asset_name=", "GET": {}, "POST": {"csrfmiddlewaretoken": "z44GIk9RrbjXsIGHPWYKp7zyHKhFlSA9QgZI47AP8p9df3qQkRgdij6iQtJ0UdkN", "next": "/#debugger", "product_id": "", "section_id": "", "project_code": "", "asset_name": ""}, "get_keys": [], "post_keys": ["csrfmiddlewaretoken", "next", "product_id", "section_id", "project_code", "asset_name"]}
block_run path=/blocks/blocks/12/run/ qs= ctype=application/x-www-form-urlencoded raw_prefix='csrfmiddlewaretoken=z44GIk9RrbjXsIGHPWYKp7zyHKhFlSA9QgZI47AP8p9df3qQkRgdij6iQtJ0UdkN&next=%2F%23debugger&product_id=&section_id=&project_code=&asset_name='
block_run recv debug: {'method': 'POST', 'path': '/blocks/blocks/12/run/', 'content_type': 'application/x-www-form-urlencoded', 'post_keys': ['csrfmiddlewaretoken', 'next', 'product_id', 'section_id', 'project_code', 'asset_name'], 'get_keys': [], 'recv_project_code': '', 'recv_project_label': '', 'recv_project_id': '', 'computed_code_from_label': '', 'computed_code_from_project_id': '', 'POST_snapshot': {'csrfmiddlewaretoken': 'z44GIk9RrbjXsIGHPWYKp7zyHKhFlSA9QgZI47AP8p9df3qQkRgdij6iQtJ0UdkN', 'next': '/#debugger', 'product_id': '', 'section_id': '', 'project_code': '', 'asset_name': ''}, 'GET_snapshot': {}, 'raw_body_2k': 'csrfmiddlewaretoken=z44GIk9RrbjXsIGHPWYKp7zyHKhFlSA9QgZI47AP8p9df3qQkRgdij6iQtJ0UdkN&next=%2F%23debugger&product_id=&section_id=&project_code=&asset_name='}
PROJECT CODE MISSING/INVALID in block_run: {'method': 'POST', 'path': '/blocks/blocks/12/run/', 'content_type': 'application/x-www-form-urlencoded', 'post_keys': ['csrfmiddlewaretoken', 'next', 'product_id', 'section_id', 'project_code', 'asset_name'], 'get_keys': [], 'recv_project_code': '', 'recv_project_label': '', 'recv_project_id': '', 'computed_code_from_label': '', 'computed_code_from_project_id': '', 'POST_snapshot': {'csrfmiddlewaretoken': 'z44GIk9RrbjXsIGHPWYKp7zyHKhFlSA9QgZI47AP8p9df3qQkRgdij6iQtJ0UdkN', 'next': '/#debugger', 'product_id': '', 'section_id': '', 'project_code': '', 'asset_name': ''}, 'GET_snapshot': {}, 'raw_body_2k': 'csrfmiddlewaretoken=z44GIk9RrbjXsIGHPWYKp7zyHKhFlSA9QgZI47AP8p9df3qQkRgdij6iQtJ0UdkN&next=%2F%23debugger&product_id=&section_id=&project_code=&asset_name='}
[24/Sep/2025 10:24:55] "POST /blocks/blocks/12/run/ HTTP/1.1" 302 0
[24/Sep/2025 10:24:55] "GET / HTTP/1.1" 200 71854
[24/Sep/2025 10:24:55] "GET /policy/policy/partial/ HTTP/1.1" 200 18425
[24/Sep/2025 10:24:55] "GET /onedrive/connections/partial/ HTTP/1.1" 200 10563
[24/Sep/2025 10:24:55] "GET /requests/partial/?product=DD&section=1 HTTP/1.1" 200 8799
[24/Sep/2025 10:24:55] "GET /projects/partial/ HTTP/1.1" 200 22372
[24/Sep/2025 10:24:55] "GET /projects/performers/partial/ HTTP/1.1" 200 10153
[24/Sep/2025 10:24:55] "GET /debugger/partial/panel/ HTTP/1.1" 200 28639
[24/Sep/2025 10:24:55] "GET /debugger/project-meta/13/ HTTP/1.1" 200 227
[24/Sep/2025 10:24:57] "GET /blocks/?tab=debugger&product=DD&section=4 HTTP/1.1" 200 128390
[24/Sep/2025 10:24:57] "GET /blocks/?tab=templates&product=DD&section=1 HTTP/1.1" 200 71946
/Users/sergei/PycharmProjects/ai_app/debugger_app/views.py changed, reloading.
Watching for file changes with StatReloader
Performing system checks...

Exception in thread django-main-thread:
Traceback (most recent call last):
  File "/Library/Frameworks/Python.framework/Versions/3.11/lib/python3.11/threading.py", line 1045, in _bootstrap_inner
    self.run()
  File "/Library/Frameworks/Python.framework/Versions/3.11/lib/python3.11/threading.py", line 982, in run
    self._target(*self._args, **self._kwargs)
  File "/Users/sergei/PycharmProjects/ai_app/.venv/lib/python3.11/site-packages/django/utils/autoreload.py", line 64, in wrapper
    fn(*args, **kwargs)
  File "/Users/sergei/PycharmProjects/ai_app/.venv/lib/python3.11/site-packages/django/core/management/commands/runserver.py", line 134, in inner_run
    self.check(**check_kwargs)
  File "/Users/sergei/PycharmProjects/ai_app/.venv/lib/python3.11/site-packages/django/core/management/base.py", line 492, in check
    all_issues = checks.run_checks(
                 ^^^^^^^^^^^^^^^^^^
  File "/Users/sergei/PycharmProjects/ai_app/.venv/lib/python3.11/site-packages/django/core/checks/registry.py", line 89, in run_checks
    new_errors = check(app_configs=app_configs, databases=databases)
                 ^^^^^^^^^^^^^^^^^^^^^^^^^^^^^^^^^^^^^^^^^^^^^^^^^^^
  File "/Users/sergei/PycharmProjects/ai_app/.venv/lib/python3.11/site-packages/django/core/checks/urls.py", line 16, in check_url_config
    return check_resolver(resolver)
           ^^^^^^^^^^^^^^^^^^^^^^^^
  File "/Users/sergei/PycharmProjects/ai_app/.venv/lib/python3.11/site-packages/django/core/checks/urls.py", line 26, in check_resolver
    return check_method()
           ^^^^^^^^^^^^^^
  File "/Users/sergei/PycharmProjects/ai_app/.venv/lib/python3.11/site-packages/django/urls/resolvers.py", line 531, in check
    for pattern in self.url_patterns:
                   ^^^^^^^^^^^^^^^^^
  File "/Users/sergei/PycharmProjects/ai_app/.venv/lib/python3.11/site-packages/django/utils/functional.py", line 47, in __get__
    res = instance.__dict__[self.name] = self.func(instance)
                                         ^^^^^^^^^^^^^^^^^^^
  File "/Users/sergei/PycharmProjects/ai_app/.venv/lib/python3.11/site-packages/django/urls/resolvers.py", line 718, in url_patterns
    patterns = getattr(self.urlconf_module, "urlpatterns", self.urlconf_module)
                       ^^^^^^^^^^^^^^^^^^^
  File "/Users/sergei/PycharmProjects/ai_app/.venv/lib/python3.11/site-packages/django/utils/functional.py", line 47, in __get__
    res = instance.__dict__[self.name] = self.func(instance)
                                         ^^^^^^^^^^^^^^^^^^^
  File "/Users/sergei/PycharmProjects/ai_app/.venv/lib/python3.11/site-packages/django/urls/resolvers.py", line 711, in urlconf_module
    return import_module(self.urlconf_name)
           ^^^^^^^^^^^^^^^^^^^^^^^^^^^^^^^^
  File "/Library/Frameworks/Python.framework/Versions/3.11/lib/python3.11/importlib/__init__.py", line 126, in import_module
    return _bootstrap._gcd_import(name[level:], package, level)
           ^^^^^^^^^^^^^^^^^^^^^^^^^^^^^^^^^^^^^^^^^^^^^^^^^^^^
  File "<frozen importlib._bootstrap>", line 1204, in _gcd_import
  File "<frozen importlib._bootstrap>", line 1176, in _find_and_load
  File "<frozen importlib._bootstrap>", line 1147, in _find_and_load_unlocked
  File "<frozen importlib._bootstrap>", line 690, in _load_unlocked
  File "<frozen importlib._bootstrap_external>", line 940, in exec_module
  File "<frozen importlib._bootstrap>", line 241, in _call_with_frames_removed
  File "/Users/sergei/PycharmProjects/ai_app/urls.py", line 18, in <module>
    path("debugger/", include("debugger_app.urls", namespace="debugger_app")),
                      ^^^^^^^^^^^^^^^^^^^^^^^^^^^^^^^^^^^^^^^^^^^^^^^^^^^^^^
  File "/Users/sergei/PycharmProjects/ai_app/.venv/lib/python3.11/site-packages/django/urls/conf.py", line 39, in include
    urlconf_module = import_module(urlconf_module)
                     ^^^^^^^^^^^^^^^^^^^^^^^^^^^^^
  File "/Library/Frameworks/Python.framework/Versions/3.11/lib/python3.11/importlib/__init__.py", line 126, in import_module
    return _bootstrap._gcd_import(name[level:], package, level)
           ^^^^^^^^^^^^^^^^^^^^^^^^^^^^^^^^^^^^^^^^^^^^^^^^^^^^
  File "<frozen importlib._bootstrap>", line 1204, in _gcd_import
  File "<frozen importlib._bootstrap>", line 1176, in _find_and_load
  File "<frozen importlib._bootstrap>", line 1147, in _find_and_load_unlocked
  File "<frozen importlib._bootstrap>", line 690, in _load_unlocked
  File "<frozen importlib._bootstrap_external>", line 940, in exec_module
  File "<frozen importlib._bootstrap>", line 241, in _call_with_frames_removed
  File "/Users/sergei/PycharmProjects/ai_app/debugger_app/urls.py", line 2, in <module>
    from . import views
  File "/Users/sergei/PycharmProjects/ai_app/debugger_app/views.py", line 9, in <module>
    from projects_app.models import Project
ImportError: cannot import name 'Project' from 'projects_app.models' (/Users/sergei/PycharmProjects/ai_app/projects_app/models.py)
/Users/sergei/PycharmProjects/ai_app/debugger_app/views.py changed, reloading.
Watching for file changes with StatReloader
Performing system checks...

Exception in thread django-main-thread:
Traceback (most recent call last):
  File "/Library/Frameworks/Python.framework/Versions/3.11/lib/python3.11/threading.py", line 1045, in _bootstrap_inner
    self.run()
  File "/Library/Frameworks/Python.framework/Versions/3.11/lib/python3.11/threading.py", line 982, in run
    self._target(*self._args, **self._kwargs)
  File "/Users/sergei/PycharmProjects/ai_app/.venv/lib/python3.11/site-packages/django/utils/autoreload.py", line 64, in wrapper
    fn(*args, **kwargs)
  File "/Users/sergei/PycharmProjects/ai_app/.venv/lib/python3.11/site-packages/django/core/management/commands/runserver.py", line 134, in inner_run
    self.check(**check_kwargs)
  File "/Users/sergei/PycharmProjects/ai_app/.venv/lib/python3.11/site-packages/django/core/management/base.py", line 492, in check
    all_issues = checks.run_checks(
                 ^^^^^^^^^^^^^^^^^^
  File "/Users/sergei/PycharmProjects/ai_app/.venv/lib/python3.11/site-packages/django/core/checks/registry.py", line 89, in run_checks
    new_errors = check(app_configs=app_configs, databases=databases)
                 ^^^^^^^^^^^^^^^^^^^^^^^^^^^^^^^^^^^^^^^^^^^^^^^^^^^
  File "/Users/sergei/PycharmProjects/ai_app/.venv/lib/python3.11/site-packages/django/core/checks/urls.py", line 16, in check_url_config
    return check_resolver(resolver)
           ^^^^^^^^^^^^^^^^^^^^^^^^
  File "/Users/sergei/PycharmProjects/ai_app/.venv/lib/python3.11/site-packages/django/core/checks/urls.py", line 26, in check_resolver
    return check_method()
           ^^^^^^^^^^^^^^
  File "/Users/sergei/PycharmProjects/ai_app/.venv/lib/python3.11/site-packages/django/urls/resolvers.py", line 531, in check
    for pattern in self.url_patterns:
                   ^^^^^^^^^^^^^^^^^
  File "/Users/sergei/PycharmProjects/ai_app/.venv/lib/python3.11/site-packages/django/utils/functional.py", line 47, in __get__
    res = instance.__dict__[self.name] = self.func(instance)
                                         ^^^^^^^^^^^^^^^^^^^
  File "/Users/sergei/PycharmProjects/ai_app/.venv/lib/python3.11/site-packages/django/urls/resolvers.py", line 718, in url_patterns
    patterns = getattr(self.urlconf_module, "urlpatterns", self.urlconf_module)
                       ^^^^^^^^^^^^^^^^^^^
  File "/Users/sergei/PycharmProjects/ai_app/.venv/lib/python3.11/site-packages/django/utils/functional.py", line 47, in __get__
    res = instance.__dict__[self.name] = self.func(instance)
                                         ^^^^^^^^^^^^^^^^^^^
  File "/Users/sergei/PycharmProjects/ai_app/.venv/lib/python3.11/site-packages/django/urls/resolvers.py", line 711, in urlconf_module
    return import_module(self.urlconf_name)
           ^^^^^^^^^^^^^^^^^^^^^^^^^^^^^^^^
  File "/Library/Frameworks/Python.framework/Versions/3.11/lib/python3.11/importlib/__init__.py", line 126, in import_module
    return _bootstrap._gcd_import(name[level:], package, level)
           ^^^^^^^^^^^^^^^^^^^^^^^^^^^^^^^^^^^^^^^^^^^^^^^^^^^^
  File "<frozen importlib._bootstrap>", line 1204, in _gcd_import
  File "<frozen importlib._bootstrap>", line 1176, in _find_and_load
  File "<frozen importlib._bootstrap>", line 1147, in _find_and_load_unlocked
  File "<frozen importlib._bootstrap>", line 690, in _load_unlocked
  File "<frozen importlib._bootstrap_external>", line 940, in exec_module
  File "<frozen importlib._bootstrap>", line 241, in _call_with_frames_removed
  File "/Users/sergei/PycharmProjects/ai_app/urls.py", line 18, in <module>
    path("debugger/", include("debugger_app.urls", namespace="debugger_app")),
                      ^^^^^^^^^^^^^^^^^^^^^^^^^^^^^^^^^^^^^^^^^^^^^^^^^^^^^^
  File "/Users/sergei/PycharmProjects/ai_app/.venv/lib/python3.11/site-packages/django/urls/conf.py", line 39, in include
    urlconf_module = import_module(urlconf_module)
                     ^^^^^^^^^^^^^^^^^^^^^^^^^^^^^
  File "/Library/Frameworks/Python.framework/Versions/3.11/lib/python3.11/importlib/__init__.py", line 126, in import_module
    return _bootstrap._gcd_import(name[level:], package, level)
           ^^^^^^^^^^^^^^^^^^^^^^^^^^^^^^^^^^^^^^^^^^^^^^^^^^^^
  File "<frozen importlib._bootstrap>", line 1204, in _gcd_import
  File "<frozen importlib._bootstrap>", line 1176, in _find_and_load
  File "<frozen importlib._bootstrap>", line 1147, in _find_and_load_unlocked
  File "<frozen importlib._bootstrap>", line 690, in _load_unlocked
  File "<frozen importlib._bootstrap_external>", line 940, in exec_module
  File "<frozen importlib._bootstrap>", line 241, in _call_with_frames_removed
  File "/Users/sergei/PycharmProjects/ai_app/debugger_app/urls.py", line 2, in <module>
    from . import views
  File "/Users/sergei/PycharmProjects/ai_app/debugger_app/views.py", line 9, in <module>
    from projects_app.models import Project
ImportError: cannot import name 'Project' from 'projects_app.models' (/Users/sergei/PycharmProjects/ai_app/projects_app/models.py)
/Users/sergei/PycharmProjects/ai_app/blocks_app/views.py changed, reloading.
Watching for file changes with StatReloader
Performing system checks...

Exception in thread django-main-thread:
Traceback (most recent call last):
  File "/Library/Frameworks/Python.framework/Versions/3.11/lib/python3.11/threading.py", line 1045, in _bootstrap_inner
    self.run()
  File "/Library/Frameworks/Python.framework/Versions/3.11/lib/python3.11/threading.py", line 982, in run
    self._target(*self._args, **self._kwargs)
  File "/Users/sergei/PycharmProjects/ai_app/.venv/lib/python3.11/site-packages/django/utils/autoreload.py", line 64, in wrapper
    fn(*args, **kwargs)
  File "/Users/sergei/PycharmProjects/ai_app/.venv/lib/python3.11/site-packages/django/core/management/commands/runserver.py", line 134, in inner_run
    self.check(**check_kwargs)
  File "/Users/sergei/PycharmProjects/ai_app/.venv/lib/python3.11/site-packages/django/core/management/base.py", line 492, in check
    all_issues = checks.run_checks(
                 ^^^^^^^^^^^^^^^^^^
  File "/Users/sergei/PycharmProjects/ai_app/.venv/lib/python3.11/site-packages/django/core/checks/registry.py", line 89, in run_checks
    new_errors = check(app_configs=app_configs, databases=databases)
                 ^^^^^^^^^^^^^^^^^^^^^^^^^^^^^^^^^^^^^^^^^^^^^^^^^^^
  File "/Users/sergei/PycharmProjects/ai_app/.venv/lib/python3.11/site-packages/django/core/checks/urls.py", line 16, in check_url_config
    return check_resolver(resolver)
           ^^^^^^^^^^^^^^^^^^^^^^^^
  File "/Users/sergei/PycharmProjects/ai_app/.venv/lib/python3.11/site-packages/django/core/checks/urls.py", line 26, in check_resolver
    return check_method()
           ^^^^^^^^^^^^^^
  File "/Users/sergei/PycharmProjects/ai_app/.venv/lib/python3.11/site-packages/django/urls/resolvers.py", line 531, in check
    for pattern in self.url_patterns:
                   ^^^^^^^^^^^^^^^^^
  File "/Users/sergei/PycharmProjects/ai_app/.venv/lib/python3.11/site-packages/django/utils/functional.py", line 47, in __get__
    res = instance.__dict__[self.name] = self.func(instance)
                                         ^^^^^^^^^^^^^^^^^^^
  File "/Users/sergei/PycharmProjects/ai_app/.venv/lib/python3.11/site-packages/django/urls/resolvers.py", line 718, in url_patterns
    patterns = getattr(self.urlconf_module, "urlpatterns", self.urlconf_module)
                       ^^^^^^^^^^^^^^^^^^^
  File "/Users/sergei/PycharmProjects/ai_app/.venv/lib/python3.11/site-packages/django/utils/functional.py", line 47, in __get__
    res = instance.__dict__[self.name] = self.func(instance)
                                         ^^^^^^^^^^^^^^^^^^^
  File "/Users/sergei/PycharmProjects/ai_app/.venv/lib/python3.11/site-packages/django/urls/resolvers.py", line 711, in urlconf_module
    return import_module(self.urlconf_name)
           ^^^^^^^^^^^^^^^^^^^^^^^^^^^^^^^^
  File "/Library/Frameworks/Python.framework/Versions/3.11/lib/python3.11/importlib/__init__.py", line 126, in import_module
    return _bootstrap._gcd_import(name[level:], package, level)
           ^^^^^^^^^^^^^^^^^^^^^^^^^^^^^^^^^^^^^^^^^^^^^^^^^^^^
  File "<frozen importlib._bootstrap>", line 1204, in _gcd_import
  File "<frozen importlib._bootstrap>", line 1176, in _find_and_load
  File "<frozen importlib._bootstrap>", line 1147, in _find_and_load_unlocked
  File "<frozen importlib._bootstrap>", line 690, in _load_unlocked
  File "<frozen importlib._bootstrap_external>", line 940, in exec_module
  File "<frozen importlib._bootstrap>", line 241, in _call_with_frames_removed
  File "/Users/sergei/PycharmProjects/ai_app/urls.py", line 18, in <module>
    path("debugger/", include("debugger_app.urls", namespace="debugger_app")),
                      ^^^^^^^^^^^^^^^^^^^^^^^^^^^^^^^^^^^^^^^^^^^^^^^^^^^^^^
  File "/Users/sergei/PycharmProjects/ai_app/.venv/lib/python3.11/site-packages/django/urls/conf.py", line 39, in include
    urlconf_module = import_module(urlconf_module)
                     ^^^^^^^^^^^^^^^^^^^^^^^^^^^^^
  File "/Library/Frameworks/Python.framework/Versions/3.11/lib/python3.11/importlib/__init__.py", line 126, in import_module
    return _bootstrap._gcd_import(name[level:], package, level)
           ^^^^^^^^^^^^^^^^^^^^^^^^^^^^^^^^^^^^^^^^^^^^^^^^^^^^
  File "<frozen importlib._bootstrap>", line 1204, in _gcd_import
  File "<frozen importlib._bootstrap>", line 1176, in _find_and_load
  File "<frozen importlib._bootstrap>", line 1147, in _find_and_load_unlocked
  File "<frozen importlib._bootstrap>", line 690, in _load_unlocked
  File "<frozen importlib._bootstrap_external>", line 940, in exec_module
  File "<frozen importlib._bootstrap>", line 241, in _call_with_frames_removed
  File "/Users/sergei/PycharmProjects/ai_app/debugger_app/urls.py", line 2, in <module>
    from . import views
  File "/Users/sergei/PycharmProjects/ai_app/debugger_app/views.py", line 9, in <module>
    from projects_app.models import Project
ImportError: cannot import name 'Project' from 'projects_app.models' (/Users/sergei/PycharmProjects/ai_app/projects_app/models.py)
/Users/sergei/PycharmProjects/ai_app/blocks_app/views.py changed, reloading.
Watching for file changes with StatReloader
Performing system checks...

Exception in thread django-main-thread:
Traceback (most recent call last):
  File "/Library/Frameworks/Python.framework/Versions/3.11/lib/python3.11/threading.py", line 1045, in _bootstrap_inner
    self.run()
  File "/Library/Frameworks/Python.framework/Versions/3.11/lib/python3.11/threading.py", line 982, in run
    self._target(*self._args, **self._kwargs)
  File "/Users/sergei/PycharmProjects/ai_app/.venv/lib/python3.11/site-packages/django/utils/autoreload.py", line 64, in wrapper
    fn(*args, **kwargs)
  File "/Users/sergei/PycharmProjects/ai_app/.venv/lib/python3.11/site-packages/django/core/management/commands/runserver.py", line 134, in inner_run
    self.check(**check_kwargs)
  File "/Users/sergei/PycharmProjects/ai_app/.venv/lib/python3.11/site-packages/django/core/management/base.py", line 492, in check
    all_issues = checks.run_checks(
                 ^^^^^^^^^^^^^^^^^^
  File "/Users/sergei/PycharmProjects/ai_app/.venv/lib/python3.11/site-packages/django/core/checks/registry.py", line 89, in run_checks
    new_errors = check(app_configs=app_configs, databases=databases)
                 ^^^^^^^^^^^^^^^^^^^^^^^^^^^^^^^^^^^^^^^^^^^^^^^^^^^
  File "/Users/sergei/PycharmProjects/ai_app/.venv/lib/python3.11/site-packages/django/core/checks/urls.py", line 16, in check_url_config
    return check_resolver(resolver)
           ^^^^^^^^^^^^^^^^^^^^^^^^
  File "/Users/sergei/PycharmProjects/ai_app/.venv/lib/python3.11/site-packages/django/core/checks/urls.py", line 26, in check_resolver
    return check_method()
           ^^^^^^^^^^^^^^
  File "/Users/sergei/PycharmProjects/ai_app/.venv/lib/python3.11/site-packages/django/urls/resolvers.py", line 531, in check
    for pattern in self.url_patterns:
                   ^^^^^^^^^^^^^^^^^
  File "/Users/sergei/PycharmProjects/ai_app/.venv/lib/python3.11/site-packages/django/utils/functional.py", line 47, in __get__
    res = instance.__dict__[self.name] = self.func(instance)
                                         ^^^^^^^^^^^^^^^^^^^
  File "/Users/sergei/PycharmProjects/ai_app/.venv/lib/python3.11/site-packages/django/urls/resolvers.py", line 718, in url_patterns
    patterns = getattr(self.urlconf_module, "urlpatterns", self.urlconf_module)
                       ^^^^^^^^^^^^^^^^^^^
  File "/Users/sergei/PycharmProjects/ai_app/.venv/lib/python3.11/site-packages/django/utils/functional.py", line 47, in __get__
    res = instance.__dict__[self.name] = self.func(instance)
                                         ^^^^^^^^^^^^^^^^^^^
  File "/Users/sergei/PycharmProjects/ai_app/.venv/lib/python3.11/site-packages/django/urls/resolvers.py", line 711, in urlconf_module
    return import_module(self.urlconf_name)
           ^^^^^^^^^^^^^^^^^^^^^^^^^^^^^^^^
  File "/Library/Frameworks/Python.framework/Versions/3.11/lib/python3.11/importlib/__init__.py", line 126, in import_module
    return _bootstrap._gcd_import(name[level:], package, level)
           ^^^^^^^^^^^^^^^^^^^^^^^^^^^^^^^^^^^^^^^^^^^^^^^^^^^^
  File "<frozen importlib._bootstrap>", line 1204, in _gcd_import
  File "<frozen importlib._bootstrap>", line 1176, in _find_and_load
  File "<frozen importlib._bootstrap>", line 1147, in _find_and_load_unlocked
  File "<frozen importlib._bootstrap>", line 690, in _load_unlocked
  File "<frozen importlib._bootstrap_external>", line 940, in exec_module
  File "<frozen importlib._bootstrap>", line 241, in _call_with_frames_removed
  File "/Users/sergei/PycharmProjects/ai_app/urls.py", line 18, in <module>
    path("debugger/", include("debugger_app.urls", namespace="debugger_app")),
                      ^^^^^^^^^^^^^^^^^^^^^^^^^^^^^^^^^^^^^^^^^^^^^^^^^^^^^^
  File "/Users/sergei/PycharmProjects/ai_app/.venv/lib/python3.11/site-packages/django/urls/conf.py", line 39, in include
    urlconf_module = import_module(urlconf_module)
                     ^^^^^^^^^^^^^^^^^^^^^^^^^^^^^
  File "/Library/Frameworks/Python.framework/Versions/3.11/lib/python3.11/importlib/__init__.py", line 126, in import_module
    return _bootstrap._gcd_import(name[level:], package, level)
           ^^^^^^^^^^^^^^^^^^^^^^^^^^^^^^^^^^^^^^^^^^^^^^^^^^^^
  File "<frozen importlib._bootstrap>", line 1204, in _gcd_import
  File "<frozen importlib._bootstrap>", line 1176, in _find_and_load
  File "<frozen importlib._bootstrap>", line 1147, in _find_and_load_unlocked
  File "<frozen importlib._bootstrap>", line 690, in _load_unlocked
  File "<frozen importlib._bootstrap_external>", line 940, in exec_module
  File "<frozen importlib._bootstrap>", line 241, in _call_with_frames_removed
  File "/Users/sergei/PycharmProjects/ai_app/debugger_app/urls.py", line 2, in <module>
    from . import views
  File "/Users/sergei/PycharmProjects/ai_app/debugger_app/views.py", line 9, in <module>
    from projects_app.models import Project
ImportError: cannot import name 'Project' from 'projects_app.models' (/Users/sergei/PycharmProjects/ai_app/projects_app/models.py)
/Users/sergei/PycharmProjects/ai_app/blocks_app/views.py changed, reloading.
Watching for file changes with StatReloader
Performing system checks...

Exception in thread django-main-thread:
Traceback (most recent call last):
  File "/Library/Frameworks/Python.framework/Versions/3.11/lib/python3.11/threading.py", line 1045, in _bootstrap_inner
    self.run()
  File "/Library/Frameworks/Python.framework/Versions/3.11/lib/python3.11/threading.py", line 982, in run
    self._target(*self._args, **self._kwargs)
  File "/Users/sergei/PycharmProjects/ai_app/.venv/lib/python3.11/site-packages/django/utils/autoreload.py", line 64, in wrapper
    fn(*args, **kwargs)
  File "/Users/sergei/PycharmProjects/ai_app/.venv/lib/python3.11/site-packages/django/core/management/commands/runserver.py", line 134, in inner_run
    self.check(**check_kwargs)
  File "/Users/sergei/PycharmProjects/ai_app/.venv/lib/python3.11/site-packages/django/core/management/base.py", line 492, in check
    all_issues = checks.run_checks(
                 ^^^^^^^^^^^^^^^^^^
  File "/Users/sergei/PycharmProjects/ai_app/.venv/lib/python3.11/site-packages/django/core/checks/registry.py", line 89, in run_checks
    new_errors = check(app_configs=app_configs, databases=databases)
                 ^^^^^^^^^^^^^^^^^^^^^^^^^^^^^^^^^^^^^^^^^^^^^^^^^^^
  File "/Users/sergei/PycharmProjects/ai_app/.venv/lib/python3.11/site-packages/django/core/checks/urls.py", line 16, in check_url_config
    return check_resolver(resolver)
           ^^^^^^^^^^^^^^^^^^^^^^^^
  File "/Users/sergei/PycharmProjects/ai_app/.venv/lib/python3.11/site-packages/django/core/checks/urls.py", line 26, in check_resolver
    return check_method()
           ^^^^^^^^^^^^^^
  File "/Users/sergei/PycharmProjects/ai_app/.venv/lib/python3.11/site-packages/django/urls/resolvers.py", line 531, in check
    for pattern in self.url_patterns:
                   ^^^^^^^^^^^^^^^^^
  File "/Users/sergei/PycharmProjects/ai_app/.venv/lib/python3.11/site-packages/django/utils/functional.py", line 47, in __get__
    res = instance.__dict__[self.name] = self.func(instance)
                                         ^^^^^^^^^^^^^^^^^^^
  File "/Users/sergei/PycharmProjects/ai_app/.venv/lib/python3.11/site-packages/django/urls/resolvers.py", line 718, in url_patterns
    patterns = getattr(self.urlconf_module, "urlpatterns", self.urlconf_module)
                       ^^^^^^^^^^^^^^^^^^^
  File "/Users/sergei/PycharmProjects/ai_app/.venv/lib/python3.11/site-packages/django/utils/functional.py", line 47, in __get__
    res = instance.__dict__[self.name] = self.func(instance)
                                         ^^^^^^^^^^^^^^^^^^^
  File "/Users/sergei/PycharmProjects/ai_app/.venv/lib/python3.11/site-packages/django/urls/resolvers.py", line 711, in urlconf_module
    return import_module(self.urlconf_name)
           ^^^^^^^^^^^^^^^^^^^^^^^^^^^^^^^^
  File "/Library/Frameworks/Python.framework/Versions/3.11/lib/python3.11/importlib/__init__.py", line 126, in import_module
    return _bootstrap._gcd_import(name[level:], package, level)
           ^^^^^^^^^^^^^^^^^^^^^^^^^^^^^^^^^^^^^^^^^^^^^^^^^^^^
  File "<frozen importlib._bootstrap>", line 1204, in _gcd_import
  File "<frozen importlib._bootstrap>", line 1176, in _find_and_load
  File "<frozen importlib._bootstrap>", line 1147, in _find_and_load_unlocked
  File "<frozen importlib._bootstrap>", line 690, in _load_unlocked
  File "<frozen importlib._bootstrap_external>", line 940, in exec_module
  File "<frozen importlib._bootstrap>", line 241, in _call_with_frames_removed
  File "/Users/sergei/PycharmProjects/ai_app/urls.py", line 18, in <module>
    path("debugger/", include("debugger_app.urls", namespace="debugger_app")),
                      ^^^^^^^^^^^^^^^^^^^^^^^^^^^^^^^^^^^^^^^^^^^^^^^^^^^^^^
  File "/Users/sergei/PycharmProjects/ai_app/.venv/lib/python3.11/site-packages/django/urls/conf.py", line 39, in include
    urlconf_module = import_module(urlconf_module)
                     ^^^^^^^^^^^^^^^^^^^^^^^^^^^^^
  File "/Library/Frameworks/Python.framework/Versions/3.11/lib/python3.11/importlib/__init__.py", line 126, in import_module
    return _bootstrap._gcd_import(name[level:], package, level)
           ^^^^^^^^^^^^^^^^^^^^^^^^^^^^^^^^^^^^^^^^^^^^^^^^^^^^
  File "<frozen importlib._bootstrap>", line 1204, in _gcd_import
  File "<frozen importlib._bootstrap>", line 1176, in _find_and_load
  File "<frozen importlib._bootstrap>", line 1147, in _find_and_load_unlocked
  File "<frozen importlib._bootstrap>", line 690, in _load_unlocked
  File "<frozen importlib._bootstrap_external>", line 940, in exec_module
  File "<frozen importlib._bootstrap>", line 241, in _call_with_frames_removed
  File "/Users/sergei/PycharmProjects/ai_app/debugger_app/urls.py", line 2, in <module>
    from . import views
  File "/Users/sergei/PycharmProjects/ai_app/debugger_app/views.py", line 9, in <module>
    from projects_app.models import Project
ImportError: cannot import name 'Project' from 'projects_app.models' (/Users/sergei/PycharmProjects/ai_app/projects_app/models.py)
/Users/sergei/PycharmProjects/ai_app/blocks_app/views.py changed, reloading.
Watching for file changes with StatReloader
Performing system checks...

Exception in thread django-main-thread:
Traceback (most recent call last):
  File "/Library/Frameworks/Python.framework/Versions/3.11/lib/python3.11/threading.py", line 1045, in _bootstrap_inner
    self.run()
  File "/Library/Frameworks/Python.framework/Versions/3.11/lib/python3.11/threading.py", line 982, in run
    self._target(*self._args, **self._kwargs)
  File "/Users/sergei/PycharmProjects/ai_app/.venv/lib/python3.11/site-packages/django/utils/autoreload.py", line 64, in wrapper
    fn(*args, **kwargs)
  File "/Users/sergei/PycharmProjects/ai_app/.venv/lib/python3.11/site-packages/django/core/management/commands/runserver.py", line 134, in inner_run
    self.check(**check_kwargs)
  File "/Users/sergei/PycharmProjects/ai_app/.venv/lib/python3.11/site-packages/django/core/management/base.py", line 492, in check
    all_issues = checks.run_checks(
                 ^^^^^^^^^^^^^^^^^^
  File "/Users/sergei/PycharmProjects/ai_app/.venv/lib/python3.11/site-packages/django/core/checks/registry.py", line 89, in run_checks
    new_errors = check(app_configs=app_configs, databases=databases)
                 ^^^^^^^^^^^^^^^^^^^^^^^^^^^^^^^^^^^^^^^^^^^^^^^^^^^
  File "/Users/sergei/PycharmProjects/ai_app/.venv/lib/python3.11/site-packages/django/core/checks/urls.py", line 16, in check_url_config
    return check_resolver(resolver)
           ^^^^^^^^^^^^^^^^^^^^^^^^
  File "/Users/sergei/PycharmProjects/ai_app/.venv/lib/python3.11/site-packages/django/core/checks/urls.py", line 26, in check_resolver
    return check_method()
           ^^^^^^^^^^^^^^
  File "/Users/sergei/PycharmProjects/ai_app/.venv/lib/python3.11/site-packages/django/urls/resolvers.py", line 531, in check
    for pattern in self.url_patterns:
                   ^^^^^^^^^^^^^^^^^
  File "/Users/sergei/PycharmProjects/ai_app/.venv/lib/python3.11/site-packages/django/utils/functional.py", line 47, in __get__
    res = instance.__dict__[self.name] = self.func(instance)
                                         ^^^^^^^^^^^^^^^^^^^
  File "/Users/sergei/PycharmProjects/ai_app/.venv/lib/python3.11/site-packages/django/urls/resolvers.py", line 718, in url_patterns
    patterns = getattr(self.urlconf_module, "urlpatterns", self.urlconf_module)
                       ^^^^^^^^^^^^^^^^^^^
  File "/Users/sergei/PycharmProjects/ai_app/.venv/lib/python3.11/site-packages/django/utils/functional.py", line 47, in __get__
    res = instance.__dict__[self.name] = self.func(instance)
                                         ^^^^^^^^^^^^^^^^^^^
  File "/Users/sergei/PycharmProjects/ai_app/.venv/lib/python3.11/site-packages/django/urls/resolvers.py", line 711, in urlconf_module
    return import_module(self.urlconf_name)
           ^^^^^^^^^^^^^^^^^^^^^^^^^^^^^^^^
  File "/Library/Frameworks/Python.framework/Versions/3.11/lib/python3.11/importlib/__init__.py", line 126, in import_module
    return _bootstrap._gcd_import(name[level:], package, level)
           ^^^^^^^^^^^^^^^^^^^^^^^^^^^^^^^^^^^^^^^^^^^^^^^^^^^^
  File "<frozen importlib._bootstrap>", line 1204, in _gcd_import
  File "<frozen importlib._bootstrap>", line 1176, in _find_and_load
  File "<frozen importlib._bootstrap>", line 1147, in _find_and_load_unlocked
  File "<frozen importlib._bootstrap>", line 690, in _load_unlocked
  File "<frozen importlib._bootstrap_external>", line 940, in exec_module
  File "<frozen importlib._bootstrap>", line 241, in _call_with_frames_removed
  File "/Users/sergei/PycharmProjects/ai_app/urls.py", line 18, in <module>
    path("debugger/", include("debugger_app.urls", namespace="debugger_app")),
                      ^^^^^^^^^^^^^^^^^^^^^^^^^^^^^^^^^^^^^^^^^^^^^^^^^^^^^^
  File "/Users/sergei/PycharmProjects/ai_app/.venv/lib/python3.11/site-packages/django/urls/conf.py", line 39, in include
    urlconf_module = import_module(urlconf_module)
                     ^^^^^^^^^^^^^^^^^^^^^^^^^^^^^
  File "/Library/Frameworks/Python.framework/Versions/3.11/lib/python3.11/importlib/__init__.py", line 126, in import_module
    return _bootstrap._gcd_import(name[level:], package, level)
           ^^^^^^^^^^^^^^^^^^^^^^^^^^^^^^^^^^^^^^^^^^^^^^^^^^^^
  File "<frozen importlib._bootstrap>", line 1204, in _gcd_import
  File "<frozen importlib._bootstrap>", line 1176, in _find_and_load
  File "<frozen importlib._bootstrap>", line 1147, in _find_and_load_unlocked
  File "<frozen importlib._bootstrap>", line 690, in _load_unlocked
  File "<frozen importlib._bootstrap_external>", line 940, in exec_module
  File "<frozen importlib._bootstrap>", line 241, in _call_with_frames_removed
  File "/Users/sergei/PycharmProjects/ai_app/debugger_app/urls.py", line 2, in <module>
    from . import views
  File "/Users/sergei/PycharmProjects/ai_app/debugger_app/views.py", line 9, in <module>
    from projects_app.models import Project
ImportError: cannot import name 'Project' from 'projects_app.models' (/Users/sergei/PycharmProjects/ai_app/projects_app/models.py)
